<?xml version="1.0" encoding="utf-8"?>
<!-- This URDF was automatically created by SolidWorks to URDF Exporter! Originally created by Stephen Brawner (brawner@gmail.com) 
     Commit Version: 1.6.0-4-g7f85cfe  Build Version: 1.6.7995.38578
     For more information, please see http://wiki.ros.org/sw_urdf_exporter -->
<robot
  name="dummy">
  
  
  <link
    name="base_link">
    <inertial>
      <origin
        xyz="0.064069 5.1162E-05 0.0085905"
        rpy="0 0 0" />
      <mass
        value="1.6762" />
      <inertia
        ixx="0.0064782"
        ixy="-4.1905E-07"
        ixz="-1.5099E-05"
        iyy="0.0090975"
        iyz="-4.5663E-07"
        izz="0.015025" />
    </inertial>
    <visual>
      <origin
        xyz="0 0 0"
        rpy="0 0 0" />
      <geometry>
        <mesh
          filename="package://dummy/meshes/base_link.STL" />
      </geometry>
      <material
        name="">
        <color
          rgba="0.79216 0.81961 0.93333 1" />
      </material>
    </visual>
    <collision>
      <origin
        xyz="0 0 0"
        rpy="0 0 0" />
      <geometry>
        <mesh
          filename="package://dummy/meshes/base_link.STL" />
      </geometry>
    </collision>
  </link>
  
  
  <link
    name="shoulder_Link">
    <inertial>
      <origin
        xyz="0.0058837 0.0056902 0.011066"
        rpy="0 0 0" />
      <mass
        value="0.053714" />
      <inertia
        ixx="1.9431E-05"
        ixy="-7.1474E-06"
        ixz="-5.1109E-06"
        iyy="2.2647E-05"
        iyz="-3.282E-06"
        izz="3.2006E-05" />
    </inertial>
    <visual>
      <origin
        xyz="0 0 0"
        rpy="0 0 0" />
      <geometry>
        <mesh
          filename="package://dummy/meshes/shoulder_Link.STL" />
      </geometry>
      <material
        name="">
        <color
          rgba="0.79216 0.81961 0.93333 1" />
      </material>
    </visual>
    <collision>
      <origin
        xyz="0 0 0"
        rpy="0 0 0" />
      <geometry>
        <mesh
          filename="package://dummy/meshes/shoulder_Link.STL" />
      </geometry>
    </collision>
  </link>
  
  
  <joint
    name="joint1"
    type="revolute">
    <origin
      xyz="0 0 0.0865"
      rpy="0 0 0" />
    <parent
      link="base_link" />
    <child
      link="shoulder_Link" />
    <axis
      xyz="0 0 1" />
    <limit
      lower="-2.97"
      upper="2.97"
      effort="150"
      velocity="3.15" />
  </joint>
  
  
  <link
    name="upper_Link">
    <inertial>
      <origin
        xyz="0.0020739 -0.070816 -0.0044564"
        rpy="0 0 0" />
      <mass
        value="0.31973" />
      <inertia
        ixx="0.00053392"
        ixy="-1.1923E-06"
        ixz="1.4352E-06"
        iyy="0.00010403"
        iyz="3.8322E-05"
        izz="0.00053419" />
    </inertial>
    <visual>
      <origin
        xyz="0 0 0"
        rpy="0 0 0" />
      <geometry>
        <mesh
          filename="package://dummy/meshes/upper_Link.STL" />
      </geometry>
      <material
        name="">
        <color
          rgba="0.79216 0.81961 0.93333 1" />
      </material>
    </visual>
    <collision>
      <origin
        xyz="0 0 0"
        rpy="0 0 0" />
      <geometry>
        <mesh
          filename="package://dummy/meshes/upper_Link.STL" />
      </geometry>
    </collision>
  </link>
  
  
  <joint
    name="joint2"
    type="revolute">
    <origin
      xyz="0.035 0 0.0275"
      rpy="-1.5708 0 0" />
    <parent
      link="shoulder_Link" />
    <child
      link="upper_Link" />
    <axis
      xyz="0 0 1" />
    <limit
      lower="-1.27"
      upper="1.57"
      effort="150"
      velocity="3.15" />
  </joint>
  
  
  <link
    name="forearm_Link">
    <inertial>
      <origin
        xyz="0.054311 -0.02026 -0.0035789"
        rpy="0 0 0" />
      <mass
        value="0.089711" />
      <inertia
        ixx="1.8295E-05"
        ixy="4.7772E-06"
        ixz="-6.0957E-06"
        iyy="3.7969E-05"
        iyz="2.2527E-06"
        izz="3.0248E-05" />
    </inertial>
    <visual>
      <origin
        xyz="0 0 0"
        rpy="0 0 0" />
      <geometry>
        <mesh
          filename="package://dummy/meshes/forearm_Link.STL" />
      </geometry>
      <material
        name="">
        <color
          rgba="0.79216 0.81961 0.93333 1" />
      </material>
    </visual>
    <collision>
      <origin
        xyz="0 0 0"
        rpy="0 0 0" />
      <geometry>
        <mesh
          filename="package://dummy/meshes/forearm_Link.STL" />
      </geometry>
    </collision>
  </link>
  
  
  <joint
    name="joint3"
    type="revolute">
    <origin
      xyz="0 -0.146 0"
      rpy="0 0 -1.5708" />
    <parent
      link="upper_Link" />
    <child
      link="forearm_Link" />
    <axis
      xyz="0 0 1" />
    <limit
      lower="-0.61"
      upper="1.57"
      effort="100"
      velocity="3.2" />
  </joint>
  
  
  <link
    name="wrist1_Link">
    <inertial>
      <origin
        xyz="-0.00014589 0.0051131 0.060438"
        rpy="0 0 0" />
      <mass
        value="0.085184" />
      <inertia
        ixx="5.4323E-05"
        ixy="3.4646E-09"
        ixz="7.7304E-08"
        iyy="5.7666E-05"
        iyz="1.8181E-06"
        izz="8.8729E-06" />
    </inertial>
    <visual>
      <origin
        xyz="0 0 0"
        rpy="0 0 0" />
      <geometry>
        <mesh
          filename="package://dummy/meshes/wrist1_Link.STL" />
      </geometry>
      <material
        name="">
        <color
          rgba="0.79216 0.81961 0.93333 1" />
      </material>
    </visual>
    <collision>
      <origin
        xyz="0 0 0"
        rpy="0 0 0" />
      <geometry>
        <mesh
          filename="package://dummy/meshes/wrist1_Link.STL" />
      </geometry>
    </collision>
  </link>
  
  
  <joint
    name="joint4"
    type="revolute">
    <origin
      xyz="0.052 0 0"
      rpy="1.5708 0 3.1416" />
    <parent
      link="forearm_Link" />
    <child
      link="wrist1_Link" />
    <axis
      xyz="0 0 1" />
    <limit
      lower="-3.14"
      upper="3.14"
      effort="50"
      velocity="3.2" />
  </joint>
  
  
  <link
    name="wrist2_Link">
    <inertial>
      <origin
        xyz="-6.7859E-06 0.039971 0.0050165"
        rpy="0 0 0" />
      <mass
        value="0.027968" />
      <inertia
        ixx="6.9036E-06"
        ixy="-1.5255E-09"
        ixz="2.427E-10"
        iyy="1.6847E-06"
        iyz="1.4886E-07"
        izz="7.2245E-06" />
    </inertial>
    <visual>
      <origin
        xyz="0 0 0"
        rpy="0 0 0" />
      <geometry>
        <mesh
          filename="package://dummy/meshes/wrist2_Link.STL" />
      </geometry>
      <material
        name="">
        <color
          rgba="0.79216 0.81961 0.93333 1" />
      </material>
    </visual>
    <collision>
      <origin
        xyz="0 0 0"
        rpy="0 0 0" />
      <geometry>
        <mesh
          filename="package://dummy/meshes/wrist2_Link.STL" />
      </geometry>
    </collision>
  </link>
  
  
  <joint
    name="joint5"
    type="revolute">
    <origin
      xyz="0 0 0.1225"
      rpy="1.5708 0 0" />
    <parent
      link="wrist1_Link" />
    <child
      link="wrist2_Link" />
    <axis
      xyz="0 0 -1" />
    <limit
      lower="-2.09"
      upper="2.09"
      effort="50"
      velocity="3.2" />
  </joint>
  
  
  <link
    name="wrist3_Link">
    <inertial>
      <origin
        xyz="0.0021192 0.0021217 0.027564"
        rpy="0 0 0" />
      <mass
        value="0.0039087" />
      <inertia
        ixx="5.6992E-07"
        ixy="1.7573E-08"
        ixz="-7.9691E-09"
        iyy="5.6998E-07"
        iyz="-7.7589E-09"
        izz="3.6006E-07" />
    </inertial>
    <visual>
      <origin
        xyz="0 0 0"
        rpy="0 0 0" />
      <geometry>
        <mesh
          filename="package://dummy/meshes/wrist3_Link.STL" />
      </geometry>
      <material
        name="">
        <color
          rgba="0.79216 0.81961 0.93333 1" />
      </material>
    </visual>
    <collision>
      <origin
        xyz="0 0 0"
        rpy="0 0 0" />
      <geometry>
        <mesh
          filename="package://dummy/meshes/wrist3_Link.STL" />
      </geometry>
    </collision>
  </link>
  
  
  <joint
    name="joint6"
    type="revolute">
    <origin
      xyz="0 0.0725 0.0005"
      rpy="-1.5708 0 0" />
    <parent
      link="wrist2_Link" />
    <child
      link="wrist3_Link" />
    <axis
      xyz="0 0 -1" />
    <limit
      lower="-12.56"
      upper="12.56"
      effort="50"
      velocity="0" />
  </joint>
</robot>
