<?xml version="1.0" encoding="utf-8" ?>
<!-- This URDF was automatically created by SolidWorks to URDF Exporter! Originally created by Stephen Brawner (brawner@gmail.com) 
     Commit Version: 1.6.0-4-g7f85cfe  Build Version: 1.6.7995.38578
     For more information, please see http://wiki.ros.org/sw_urdf_exporter -->
<robot name="dummy">

    <!-- LINKS -->
    <link name="world"/>

    <joint name="fixed" type="fixed">
    <parent link="world"/>
        <child link="base_link"/>
    </joint>

    <link name="base_link">
        <inertial>
            <origin xyz="0.064069 5.1162E-05 0.0085905" rpy="0 0 0" />
            <mass value="0.1" />
            <inertia ixx="0.3" ixy="0" ixz="0" iyy="0.3" iyz="0" izz="0.3" />
        </inertial>
        <visual>
            <origin xyz="0 0 0" rpy="0 0 0" />
            <geometry>
                <mesh filename="package://dummy/meshes/base_link.STL" />
            </geometry>
            <material name="">
                <color rgba="0.79216 0.81961 0.93333 1" />
            </material>
        </visual>
        <collision>
            <origin xyz="0 0 0" rpy="0 0 0" />
            <geometry>
                <mesh filename="package://dummy/meshes/base_link.STL" />
            </geometry>
        </collision>
    </link>

    <link name="shoulder_Link">
        <inertial>
            <origin xyz="0.0058837 0.0056902 0.011066" rpy="0 0 0" />
            <mass value="0.1" />
            <inertia ixx="0.1" ixy="0" ixz="0" iyy="0.1" iyz="0" izz="0.1" />
        </inertial>
        <visual>
            <origin xyz="0 0 0" rpy="0 0 0" />
            <geometry>
                <mesh filename="package://dummy/meshes/shoulder_Link.STL" />
            </geometry>
            <material name="">
                <color rgba="0.79216 0.81961 0.93333 1" />
            </material>
        </visual>
        <collision>
            <origin xyz="0 0 0" rpy="0 0 0" />
            <geometry>
                <mesh filename="package://dummy/meshes/shoulder_Link.STL" />
            </geometry>
        </collision>
    </link>
    
    <link name="upper_Link">
        <inertial>
            <origin xyz="0.0020739 -0.070816 -0.0044564" rpy="0 0 0" />
            <mass value="0.1" />
            <inertia ixx="0.1" ixy="0" ixz="0" iyy="0.01" iyz="0" izz="0.01" />
        </inertial>
        <visual>
            <origin xyz="0 0 0" rpy="0 0 0" />
            <geometry>
                <mesh filename="package://dummy/meshes/upper_Link.STL" />
            </geometry>
            <material name="">
                <color rgba="0.79216 0.81961 0.93333 1" />
            </material>
        </visual>
        <collision>
            <origin xyz="0 0 0" rpy="0 0 0" />
            <geometry>
                <mesh filename="package://dummy/meshes/upper_Link.STL" />
            </geometry>
        </collision>
    </link>
    
    <link name="forearm_Link">
        <inertial>
            <origin xyz="0.054311 -0.02026 -0.0035789" rpy="0 0 0" />
            <mass value="0.1" />
            <inertia ixx="0.01" ixy="0" ixz="0" iyy="0.01" iyz="0" izz="0.01" />
        </inertial>
        <visual>
            <origin xyz="0 0 0" rpy="0 0 0" />
            <geometry>
                <mesh filename="package://dummy/meshes/forearm_Link.STL" />
            </geometry>
            <material name="">
                <color rgba="0.79216 0.81961 0.93333 1" />
            </material>
        </visual>
        <collision>
            <origin xyz="0 0 0" rpy="0 0 0" />
            <geometry>
                <mesh filename="package://dummy/meshes/forearm_Link.STL" />
            </geometry>
        </collision>
    </link>
    
    <link name="wrist1_Link">
        <inertial>
            <origin xyz="-0.00014589 0.0051131 0.060438" rpy="0 0 0" />
            <mass value="0.1" />
            <inertia ixx="0.01" ixy="0" ixz="0" iyy="0.01" iyz="0" izz="0" />
        </inertial>
        <visual>
            <origin xyz="0 0 0" rpy="0 0 0" />
            <geometry>
                <mesh filename="package://dummy/meshes/wrist1_Link.STL" />
            </geometry>
            <material name="">
                <color rgba="0.79216 0.81961 0.93333 1" />
            </material>
        </visual>
        <collision>
            <origin xyz="0 0 0" rpy="0 0 0" />
            <geometry>
                <mesh filename="package://dummy/meshes/wrist1_Link.STL" />
            </geometry>
        </collision>
    </link>
    
    <link name="wrist2_Link">
        <inertial>
            <origin xyz="-6.7859E-06 0.039971 0.0050165" rpy="0 0 0" />
            <mass value="0.1" />
            <inertia ixx="0" ixy="0" ixz="2.427E-10" iyy="0" iyz="0" izz="0" />
        </inertial>
        <visual>
            <origin xyz="0 0 0" rpy="0 0 0" />
            <geometry>
                <mesh filename="package://dummy/meshes/wrist2_Link.STL" />
            </geometry>
            <material name="">
                <color rgba="0.79216 0.81961 0.93333 1" />
            </material>
        </visual>
        <collision>
            <origin xyz="0 0 0" rpy="0 0 0" />
            <geometry>
                <mesh filename="package://dummy/meshes/wrist2_Link.STL" />
            </geometry>
        </collision>
    </link>
    
    <link name="wrist3_Link">
        <inertial>
            <origin xyz="0.0021192 0.0021217 0.027564" rpy="0 0 0" />
            <mass value="0.1" />
            <inertia ixx="0" ixy="0" ixz="0" iyy="0" iyz="0" izz="0" />
        </inertial>
        <visual>
            <origin xyz="0 0 0" rpy="0 0 0" />
            <geometry>
                <mesh filename="package://dummy/meshes/wrist3_Link.STL" />
            </geometry>
            <material name="">
                <color rgba="0.79216 0.81961 0.93333 1" />
            </material>
        </visual>
        <collision>
            <origin xyz="0 0 0" rpy="0 0 0" />
            <geometry>
                <mesh filename="package://dummy/meshes/wrist3_Link.STL" />
            </geometry>
        </collision>
    </link>



    <!-- JOINTS -->
    <joint name="joint1" type="revolute">
        <origin xyz="0 0 0.0865" rpy="0 0 0" />
        <parent link="base_link" />
        <child link="shoulder_Link" />
        <axis xyz="0 0 1" />
        <limit lower="-2.97" upper="2.97" effort="30" velocity="3" />
    </joint>

    <joint name="joint2" type="revolute">
        <origin xyz="0.035 0 0.0275" rpy="-1.5708 0 0" />
        <parent link="shoulder_Link" />
        <child link="upper_Link" />
        <axis xyz="0 0 1" />
        <limit lower="-1.27" upper="1.57" effort="30" velocity="3" />
    </joint>

    <joint name="joint3" type="revolute">
        <origin xyz="0 -0.146 0" rpy="0 0 -1.5708" />
        <parent link="upper_Link" />
        <child link="forearm_Link" />
        <axis xyz="0 0 1" />
        <limit lower="-0.61" upper="1.57" effort="20" velocity="3" />
    </joint>

    <joint name="joint4" type="revolute">
        <origin xyz="0.052 0 0" rpy="1.5708 0 3.1416" />
        <parent link="forearm_Link" />
        <child link="wrist1_Link" />
        <axis xyz="0 0 1" />
        <limit lower="-3.14" upper="3.14" effort="10" velocity="3" />
    </joint>

    <joint name="joint5" type="revolute">
        <origin xyz="0 0 0.1225" rpy="1.5708 0 0" />
        <parent link="wrist1_Link" />
        <child link="wrist2_Link" />
        <axis xyz="0 0 -1" />
        <limit lower="-2.09" upper="2.09" effort="10" velocity="3" />
    </joint>

    <joint name="joint6" type="revolute">
        <origin xyz="0 0.0725 0.0005" rpy="-1.5708 0 0" />
        <parent link="wrist2_Link" />
        <child link="wrist3_Link" />
        <axis xyz="0 0 -1" />
        <limit lower="-12.56" upper="12.56" effort="10" velocity="3" />
    </joint>



    <transmission name="trans_joint1">
        <type>transmission_interface/SimpleTransmission</type>
        <joint name="joint1">
            <hardwareInterface>hardware_interface/EffortJointInterface</hardwareInterface>
        </joint>
        <actuator name="joint1_motor">
            <hardwareInterface>hardware_interface/EffortJointInterface</hardwareInterface>
            <mechanicalReduction>1</mechanicalReduction>
        </actuator>
    </transmission>
    <transmission name="trans_joint2">
        <type>transmission_interface/SimpleTransmission</type>
        <joint name="joint2">
            <hardwareInterface>hardware_interface/EffortJointInterface</hardwareInterface>
        </joint>
        <actuator name="joint2_motor">
            <hardwareInterface>hardware_interface/EffortJointInterface</hardwareInterface>
            <mechanicalReduction>1</mechanicalReduction>
        </actuator>
    </transmission>
    <transmission name="trans_joint3">
        <type>transmission_interface/SimpleTransmission</type>
        <joint name="joint3">
            <hardwareInterface>hardware_interface/EffortJointInterface</hardwareInterface>
        </joint>
        <actuator name="joint3_motor">
            <hardwareInterface>hardware_interface/EffortJointInterface</hardwareInterface>
            <mechanicalReduction>1</mechanicalReduction>
        </actuator>
    </transmission>
    <transmission name="trans_joint4">
        <type>transmission_interface/SimpleTransmission</type>
        <joint name="joint4">
            <hardwareInterface>hardware_interface/EffortJointInterface</hardwareInterface>
        </joint>
        <actuator name="joint4_motor">
            <hardwareInterface>hardware_interface/EffortJointInterface</hardwareInterface>
            <mechanicalReduction>1</mechanicalReduction>
        </actuator>
    </transmission>
    <transmission name="trans_joint5">
        <type>transmission_interface/SimpleTransmission</type>
        <joint name="joint5">
            <hardwareInterface>hardware_interface/EffortJointInterface</hardwareInterface>
        </joint>
        <actuator name="joint5_motor">
            <hardwareInterface>hardware_interface/EffortJointInterface</hardwareInterface>
            <mechanicalReduction>1</mechanicalReduction>
        </actuator>
    </transmission>
    <transmission name="trans_joint6">
        <type>transmission_interface/SimpleTransmission</type>
        <joint name="joint6">
            <hardwareInterface>hardware_interface/EffortJointInterface</hardwareInterface>
        </joint>
        <actuator name="joint6_motor">
            <hardwareInterface>hardware_interface/EffortJointInterface</hardwareInterface>
            <mechanicalReduction>1</mechanicalReduction>
        </actuator>
    </transmission>
    <gazebo>
        <plugin name="gazebo_ros_control" filename="libgazebo_ros_control.so">
            <robotNamespace>/</robotNamespace>
        </plugin>
    </gazebo>
</robot>
